[2025-09-03 10:21:16,979: INFO: main : welcome to your first project]
[2025-09-04 11:49:33,093: INFO: common : yaml file: config\config.yaml loaded succesfully]
[2025-09-04 11:54:47,590: INFO: common : yaml file: config\config.yaml loaded succesfully]
[2025-09-04 11:54:56,152: INFO: common : yaml file: config\config.yaml loaded succesfully]
[2025-09-04 12:07:02,280: INFO: common : yaml file: config\config.yaml loaded succesfully]
[2025-09-04 12:09:38,448: INFO: common : yaml file: config\config.yaml loaded succesfully]
[2025-09-04 12:09:45,650: INFO: common : yaml file: config\config.yaml loaded succesfully]
[2025-09-04 12:11:23,156: INFO: common : yaml file: config\config.yaml loaded succesfully]
[2025-09-04 12:11:29,970: INFO: common : yaml file: config\config.yaml loaded succesfully]
[2025-09-04 12:12:28,414: INFO: common : yaml file: config\config.yaml loaded succesfully]
[2025-09-04 12:13:43,374: INFO: common : yaml file: config\config.yaml loaded succesfully]
[2025-09-04 12:18:58,929: INFO: common : yaml file: config\config.yaml loaded succesfully]
[2025-09-04 12:19:14,936: INFO: common : yaml file: config\config.yaml loaded succesfully]
[2025-09-04 12:21:43,690: INFO: common : yaml file: config\config.yaml loaded succesfully]
[2025-09-04 12:23:28,515: INFO: common : yaml file: config\config.yaml loaded succesfully]
[2025-09-04 12:24:28,547: INFO: common : yaml file: config\config.yaml loaded succesfully]
[2025-09-04 12:31:32,318: INFO: common : yaml file: config\config.yaml loaded succesfully]
[2025-09-04 12:33:32,398: INFO: common : yaml file: config\config.yaml loaded succesfully]
[2025-09-04 12:35:11,193: INFO: common : yaml file: config\config.yaml loaded succesfully]
[2025-09-04 12:40:09,961: INFO: common : yaml file: config\config.yaml loaded succesfully]
[2025-09-04 12:44:09,513: INFO: common : yaml file: config\config.yaml loaded succesfully]
[2025-09-04 12:45:06,475: INFO: common : created directory at: artifacts]
[2025-09-04 12:45:06,482: INFO: common : created directory at: artifacts/data_ingestion]
[2025-09-04 12:47:18,471: INFO: common : created directory at: artifacts]
[2025-09-04 12:47:18,473: INFO: common : created directory at: artifacts/data_ingestion]
[2025-09-04 12:47:20,027: INFO: 106677922 : artifacts/data_ingestion/data.zip download! with following info: 
Connection: close
Content-Length: 23329
Cache-Control: max-age=300
Content-Security-Policy: default-src 'none'; style-src 'unsafe-inline'; sandbox
Content-Type: application/zip
ETag: "c69888a4ae59bc5a893392785a938ccd4937981c06ba8a9d6a21aa52b4ab5b6e"
Strict-Transport-Security: max-age=31536000
X-Content-Type-Options: nosniff
X-Frame-Options: deny
X-XSS-Protection: 1; mode=block
X-GitHub-Request-Id: D81A:218E7D:CA940:224F21:68B93CFE
Accept-Ranges: bytes
Date: Thu, 04 Sep 2025 07:17:19 GMT
Via: 1.1 varnish
X-Served-By: cache-ccu830021-CCU
X-Cache: MISS
X-Cache-Hits: 0
X-Timer: S1756970239.459845,VS0,VE258
Vary: Authorization,Accept-Encoding
Access-Control-Allow-Origin: *
Cross-Origin-Resource-Policy: cross-origin
X-Fastly-Request-ID: 664ad38a5e0be5483c07d41480cf168f0288518f
Expires: Thu, 04 Sep 2025 07:22:19 GMT
Source-Age: 0

]
[2025-09-04 13:27:49,764: INFO: main : >>>>>> stage Data Ingestion stage started <<<<<<]
[2025-09-04 13:27:49,807: INFO: common : created directory at: artifacts]
[2025-09-04 13:27:49,809: INFO: common : created directory at: artifacts/data_ingestion]
[2025-09-04 13:27:51,410: INFO: data_ingestion : artifacts/data_ingestion/data.zip download! with following info: 
Connection: close
Content-Length: 23329
Cache-Control: max-age=300
Content-Security-Policy: default-src 'none'; style-src 'unsafe-inline'; sandbox
Content-Type: application/zip
ETag: "c69888a4ae59bc5a893392785a938ccd4937981c06ba8a9d6a21aa52b4ab5b6e"
Strict-Transport-Security: max-age=31536000
X-Content-Type-Options: nosniff
X-Frame-Options: deny
X-XSS-Protection: 1; mode=block
X-GitHub-Request-Id: D81A:218E7D:CA940:224F21:68B93CFE
Accept-Ranges: bytes
Date: Thu, 04 Sep 2025 07:57:51 GMT
Via: 1.1 varnish
X-Served-By: cache-ccu830037-CCU
X-Cache: HIT
X-Cache-Hits: 0
X-Timer: S1756972671.909358,VS0,VE283
Vary: Authorization,Accept-Encoding
Access-Control-Allow-Origin: *
Cross-Origin-Resource-Policy: cross-origin
X-Fastly-Request-ID: 99bcd7f3ee77343a72dba50862aaf891f53f7d18
Expires: Thu, 04 Sep 2025 08:02:51 GMT
Source-Age: 0

]
[2025-09-04 13:27:51,441: INFO: main : >>>>>> stage Data Ingestion stage completed <<<<<<

x==========x]
[2025-09-04 15:12:36,756: INFO: common : created directory at: artifacts]
[2025-09-04 15:12:36,758: INFO: common : created directory at: artifacts/data_validation]
[2025-09-04 15:24:27,368: INFO: common : created directory at: artifacts]
[2025-09-04 15:24:27,371: INFO: common : created directory at: artifacts/data_validation]
[2025-09-04 15:24:34,231: INFO: common : created directory at: artifacts]
[2025-09-04 15:24:34,234: INFO: common : created directory at: artifacts/data_validation]
[2025-09-04 15:35:26,678: INFO: main : >>>>>> stage Data Ingestion stage started <<<<<<]
[2025-09-04 15:35:26,683: INFO: common : created directory at: artifacts]
[2025-09-04 15:35:26,684: ERROR: main : 'ConfigurationManager' object has no attribute 'get_data_ingestion_config']
Traceback (most recent call last):
  File "D:\data science and AI\2. MLOPS COURSE BY KRISH\14. First Project\byme\datascineceproject\main.py", line 8, in <module>
    data_ingestion.initiate_data_ingestion()
  File "D:\data science and AI\2. MLOPS COURSE BY KRISH\14. First Project\byme\datascineceproject\src\datascience\pipeline\data_ingestion_pipeline.py", line 13, in initiate_data_ingestion
    data_ingestion_config=config.get_data_ingestion_config()
AttributeError: 'ConfigurationManager' object has no attribute 'get_data_ingestion_config'
[2025-09-04 15:36:11,280: INFO: main : >>>>>> stage Data Ingestion stage started <<<<<<]
[2025-09-04 15:36:11,288: INFO: common : created directory at: artifacts]
[2025-09-04 15:36:11,289: ERROR: main : 'ConfigurationManager' object has no attribute 'get_data_ingestion_config']
Traceback (most recent call last):
  File "D:\data science and AI\2. MLOPS COURSE BY KRISH\14. First Project\byme\datascineceproject\main.py", line 8, in <module>
    data_ingestion.initiate_data_ingestion()
  File "D:\data science and AI\2. MLOPS COURSE BY KRISH\14. First Project\byme\datascineceproject\src\datascience\pipeline\data_ingestion_pipeline.py", line 13, in initiate_data_ingestion
    data_ingestion_config=config.get_data_ingestion_config()
AttributeError: 'ConfigurationManager' object has no attribute 'get_data_ingestion_config'
[2025-09-04 15:37:11,185: INFO: main : >>>>>> stage Data Ingestion stage started <<<<<<]
[2025-09-04 15:37:11,192: INFO: common : created directory at: artifacts]
[2025-09-04 15:37:11,193: INFO: common : created directory at: artifacts/data_ingestion]
[2025-09-04 15:37:12,603: INFO: data_ingestion : artifacts/data_ingestion/data.zip download! with following info: 
Connection: close
Content-Length: 23329
Cache-Control: max-age=300
Content-Security-Policy: default-src 'none'; style-src 'unsafe-inline'; sandbox
Content-Type: application/zip
ETag: "c69888a4ae59bc5a893392785a938ccd4937981c06ba8a9d6a21aa52b4ab5b6e"
Strict-Transport-Security: max-age=31536000
X-Content-Type-Options: nosniff
X-Frame-Options: deny
X-XSS-Protection: 1; mode=block
X-GitHub-Request-Id: 47D8:1B0BD4:106721:29E027:68B964CE
Accept-Ranges: bytes
Date: Thu, 04 Sep 2025 10:07:12 GMT
Via: 1.1 varnish
X-Served-By: cache-ccu830025-CCU
X-Cache: MISS
X-Cache-Hits: 0
X-Timer: S1756980432.039267,VS0,VE285
Vary: Authorization,Accept-Encoding
Access-Control-Allow-Origin: *
Cross-Origin-Resource-Policy: cross-origin
X-Fastly-Request-ID: 2302d2d384ed228548fbc1bbd2e74aa98db65ec0
Expires: Thu, 04 Sep 2025 10:12:12 GMT
Source-Age: 0

]
[2025-09-04 15:37:12,645: INFO: main : >>>>>> stage Data Ingestion stage completed <<<<<<

x==========x]
[2025-09-04 15:37:12,645: INFO: main : >>>>>> stage Data Validation stage started <<<<<<]
[2025-09-04 15:37:12,656: INFO: common : created directory at: artifacts]
[2025-09-04 15:37:12,657: INFO: common : created directory at: artifacts/data_validation]
[2025-09-04 15:37:12,657: ERROR: main : local variable 'data_validation' referenced before assignment]
Traceback (most recent call last):
  File "D:\data science and AI\2. MLOPS COURSE BY KRISH\14. First Project\byme\datascineceproject\main.py", line 19, in <module>
    data_ingestion.initiate_data_validation()
  File "D:\data science and AI\2. MLOPS COURSE BY KRISH\14. First Project\byme\datascineceproject\src\datascience\pipeline\data_validation_pipeline.py", line 13, in initiate_data_validation
    data_validation = data_validation(config=data_validation_config)
UnboundLocalError: local variable 'data_validation' referenced before assignment
[2025-09-04 15:38:23,664: INFO: main : >>>>>> stage Data Ingestion stage started <<<<<<]
[2025-09-04 15:38:23,670: INFO: common : created directory at: artifacts]
[2025-09-04 15:38:23,670: INFO: common : created directory at: artifacts/data_ingestion]
[2025-09-04 15:38:23,671: INFO: data_ingestion : File already exists]
[2025-09-04 15:38:23,676: INFO: main : >>>>>> stage Data Ingestion stage completed <<<<<<

x==========x]
[2025-09-04 15:38:23,676: INFO: main : >>>>>> stage Data Validation stage started <<<<<<]
[2025-09-04 15:38:23,683: INFO: common : created directory at: artifacts]
[2025-09-04 15:38:23,684: INFO: common : created directory at: artifacts/data_validation]
[2025-09-04 15:38:23,697: INFO: main : >>>>>> stage Data Validation stage completed <<<<<<

x==========x]
[2025-09-05 10:59:31,059: INFO: utils : NumExpr defaulting to 8 threads.]
[2025-09-05 11:01:58,902: INFO: utils : NumExpr defaulting to 8 threads.]
[2025-09-05 11:02:00,615: INFO: main : >>>>>> stage Data Ingestion stage started <<<<<<]
[2025-09-05 11:02:00,634: INFO: common : created directory at: artifacts]
[2025-09-05 11:02:00,635: INFO: common : created directory at: artifacts/data_ingestion]
[2025-09-05 11:02:00,635: INFO: data_ingestion : File already exists]
[2025-09-05 11:02:00,764: INFO: main : >>>>>> stage Data Ingestion stage completed <<<<<<

x==========x]
[2025-09-05 11:02:00,765: INFO: main : >>>>>> stage Data Validation stage started <<<<<<]
[2025-09-05 11:02:00,769: INFO: common : created directory at: artifacts]
[2025-09-05 11:02:00,770: INFO: common : created directory at: artifacts/data_validation]
[2025-09-05 11:02:00,790: INFO: main : >>>>>> stage Data Validation stage completed <<<<<<

x==========x]
[2025-09-05 11:02:00,791: INFO: main : >>>>>> stage Data Transformation stage started <<<<<<]
[2025-09-05 11:02:00,795: INFO: common : created directory at: artifacts]
[2025-09-05 11:02:00,795: ERROR: main : 'ConfigurationManager' object has no attribute 'get_data_tranformation_config']
Traceback (most recent call last):
  File "D:\data science and AI\2. MLOPS COURSE BY KRISH\14. First Project\byme\datascineceproject\main.py", line 31, in <module>
    obj.initiate_data_transformation()
  File "D:\data science and AI\2. MLOPS COURSE BY KRISH\14. First Project\byme\datascineceproject\src\datascience\pipeline\data_transformation_pipeline.py", line 13, in initiate_data_transformation
    data_transformation_config=config.get_data_tranformation_config()
                               ^^^^^^^^^^^^^^^^^^^^^^^^^^^^^^^^^^^^
AttributeError: 'ConfigurationManager' object has no attribute 'get_data_tranformation_config'. Did you mean: 'get_data_transformation_config'?
[2025-09-05 11:04:18,336: INFO: utils : NumExpr defaulting to 8 threads.]
[2025-09-05 11:04:19,501: INFO: main : >>>>>> stage Data Ingestion stage started <<<<<<]
[2025-09-05 11:04:19,506: INFO: common : created directory at: artifacts]
[2025-09-05 11:04:19,506: INFO: common : created directory at: artifacts/data_ingestion]
[2025-09-05 11:04:19,506: INFO: data_ingestion : File already exists]
[2025-09-05 11:04:19,508: INFO: main : >>>>>> stage Data Ingestion stage completed <<<<<<

x==========x]
[2025-09-05 11:04:19,509: INFO: main : >>>>>> stage Data Validation stage started <<<<<<]
[2025-09-05 11:04:19,514: INFO: common : created directory at: artifacts]
[2025-09-05 11:04:19,515: INFO: common : created directory at: artifacts/data_validation]
[2025-09-05 11:04:19,526: INFO: main : >>>>>> stage Data Validation stage completed <<<<<<

x==========x]
[2025-09-05 11:04:19,526: INFO: main : >>>>>> stage Data Transformation stage started <<<<<<]
[2025-09-05 11:04:19,532: INFO: common : created directory at: artifacts]
[2025-09-05 11:04:19,532: INFO: common : created directory at: artifacts/data_transformation]
[2025-09-05 11:04:19,532: ERROR: main : 'DataTransformation' object has no attribute 'train_test_splitting']
Traceback (most recent call last):
  File "D:\data science and AI\2. MLOPS COURSE BY KRISH\14. First Project\byme\datascineceproject\main.py", line 31, in <module>
    obj.initiate_data_transformation()
  File "D:\data science and AI\2. MLOPS COURSE BY KRISH\14. First Project\byme\datascineceproject\src\datascience\pipeline\data_transformation_pipeline.py", line 15, in initiate_data_transformation
    data_transformation.train_test_splitting()
    ^^^^^^^^^^^^^^^^^^^^^^^^^^^^^^^^^^^^^^^^
AttributeError: 'DataTransformation' object has no attribute 'train_test_splitting'. Did you mean: 'train_test_spliting'?
[2025-09-05 11:04:40,536: INFO: utils : NumExpr defaulting to 8 threads.]
[2025-09-05 11:04:41,642: INFO: main : >>>>>> stage Data Ingestion stage started <<<<<<]
[2025-09-05 11:04:41,647: INFO: common : created directory at: artifacts]
[2025-09-05 11:04:41,648: INFO: common : created directory at: artifacts/data_ingestion]
[2025-09-05 11:04:41,648: INFO: data_ingestion : File already exists]
[2025-09-05 11:04:41,652: INFO: main : >>>>>> stage Data Ingestion stage completed <<<<<<

x==========x]
[2025-09-05 11:04:41,652: INFO: main : >>>>>> stage Data Validation stage started <<<<<<]
[2025-09-05 11:04:41,658: INFO: common : created directory at: artifacts]
[2025-09-05 11:04:41,659: INFO: common : created directory at: artifacts/data_validation]
[2025-09-05 11:04:41,670: INFO: main : >>>>>> stage Data Validation stage completed <<<<<<

x==========x]
[2025-09-05 11:04:41,670: INFO: main : >>>>>> stage Data Transformation stage started <<<<<<]
[2025-09-05 11:04:41,675: INFO: common : created directory at: artifacts]
[2025-09-05 11:04:41,676: INFO: common : created directory at: artifacts/data_transformation]
[2025-09-05 11:04:41,803: INFO: data_transformation : Splited data into training and test sets]
[2025-09-05 11:04:41,804: INFO: data_transformation : (1199, 12)]
[2025-09-05 11:04:41,804: INFO: data_transformation : (400, 12)]
[2025-09-05 11:04:41,805: INFO: main : >>>>>> stage Data Transformation stage completed <<<<<<

x==========x]
[2025-09-05 12:39:43,788: INFO: utils : NumExpr defaulting to 8 threads.]
[2025-09-05 12:39:45,808: INFO: main : >>>>>> stage Data Ingestion stage started <<<<<<]
[2025-09-05 12:39:45,814: INFO: common : created directory at: artifacts]
[2025-09-05 12:39:45,814: INFO: common : created directory at: artifacts/data_ingestion]
[2025-09-05 12:39:45,815: INFO: data_ingestion : File already exists]
[2025-09-05 12:39:45,820: INFO: main : >>>>>> stage Data Ingestion stage completed <<<<<<

x==========x]
[2025-09-05 12:39:45,821: INFO: main : >>>>>> stage Data Validation stage started <<<<<<]
[2025-09-05 12:39:45,828: INFO: common : created directory at: artifacts]
[2025-09-05 12:39:45,829: INFO: common : created directory at: artifacts/data_validation]
[2025-09-05 12:39:45,842: INFO: main : >>>>>> stage Data Validation stage completed <<<<<<

x==========x]
[2025-09-05 12:39:45,843: INFO: main : >>>>>> stage Data Transformation stage started <<<<<<]
[2025-09-05 12:39:45,849: INFO: common : created directory at: artifacts]
[2025-09-05 12:39:45,850: INFO: common : created directory at: artifacts/data_transformation]
[2025-09-05 12:39:45,893: INFO: data_transformation : Splited data into training and test sets]
[2025-09-05 12:39:45,893: INFO: data_transformation : (1199, 12)]
[2025-09-05 12:39:45,894: INFO: data_transformation : (400, 12)]
[2025-09-05 12:39:45,894: INFO: main : >>>>>> stage Data Transformation stage completed <<<<<<

x==========x]
[2025-09-05 12:39:45,894: INFO: main : >>>>>> stage Model Training stage started <<<<<<]
[2025-09-05 12:39:45,899: INFO: common : created directory at: artifacts]
[2025-09-05 12:39:45,971: ERROR: main : [Errno 2] No such file or directory: 'artifacts/model_trainer\\model.joblib']
Traceback (most recent call last):
  File "D:\data science and AI\2. MLOPS COURSE BY KRISH\14. First Project\byme\datascineceproject\main.py", line 44, in <module>
    obj.initiate_model_training()
  File "D:\data science and AI\2. MLOPS COURSE BY KRISH\14. First Project\byme\datascineceproject\src\datascience\pipeline\model_trainer_pipeline.py", line 16, in initiate_model_training
    model_trainer.train()
  File "D:\data science and AI\2. MLOPS COURSE BY KRISH\14. First Project\byme\datascineceproject\src\datascience\components\model_trainer.py", line 24, in train
    joblib.dump(lr,os.path.join(self.config.root_dir, self.config.model_name))
  File "C:\Users\hp\anaconda3\Lib\site-packages\joblib\numpy_pickle.py", line 552, in dump
    with open(filename, 'wb') as f:
         ^^^^^^^^^^^^^^^^^^^^
FileNotFoundError: [Errno 2] No such file or directory: 'artifacts/model_trainer\\model.joblib'
[2025-09-05 12:41:46,160: INFO: utils : NumExpr defaulting to 8 threads.]
[2025-09-05 12:41:47,808: INFO: main : >>>>>> stage Data Ingestion stage started <<<<<<]
[2025-09-05 12:41:47,817: INFO: common : created directory at: artifacts]
[2025-09-05 12:41:47,817: INFO: common : created directory at: artifacts/data_ingestion]
[2025-09-05 12:41:47,818: INFO: data_ingestion : File already exists]
[2025-09-05 12:41:47,823: INFO: main : >>>>>> stage Data Ingestion stage completed <<<<<<

x==========x]
[2025-09-05 12:41:47,823: INFO: main : >>>>>> stage Data Validation stage started <<<<<<]
[2025-09-05 12:41:47,830: INFO: common : created directory at: artifacts]
[2025-09-05 12:41:47,831: INFO: common : created directory at: artifacts/data_validation]
[2025-09-05 12:41:47,847: INFO: main : >>>>>> stage Data Validation stage completed <<<<<<

x==========x]
[2025-09-05 12:41:47,847: INFO: main : >>>>>> stage Data Transformation stage started <<<<<<]
[2025-09-05 12:41:47,854: INFO: common : created directory at: artifacts]
[2025-09-05 12:41:47,855: INFO: common : created directory at: artifacts/data_transformation]
[2025-09-05 12:41:47,898: INFO: data_transformation : Splited data into training and test sets]
[2025-09-05 12:41:47,899: INFO: data_transformation : (1199, 12)]
[2025-09-05 12:41:47,900: INFO: data_transformation : (400, 12)]
[2025-09-05 12:41:47,900: INFO: main : >>>>>> stage Data Transformation stage completed <<<<<<

x==========x]
[2025-09-05 12:41:47,901: INFO: main : >>>>>> stage Model Training stage started <<<<<<]
[2025-09-05 12:41:47,906: INFO: common : created directory at: artifacts]
[2025-09-05 12:41:47,907: INFO: common : created directory at: artifacts/model_trainer]
[2025-09-05 12:41:47,964: INFO: main : >>>>>> stage Model Training stage completed <<<<<<

x==========x]
[2025-09-06 11:15:24,178: INFO: common : created directory at: artifacts]
[2025-09-06 11:15:24,196: INFO: common : created directory at: artifacts/model_evaluation]
[2025-09-06 11:31:58,345: INFO: utils : NumExpr defaulting to 8 threads.]
[2025-09-06 11:32:04,106: INFO: main : >>>>>> stage Data Ingestion stage started <<<<<<]
[2025-09-06 11:32:04,120: INFO: common : created directory at: artifacts]
[2025-09-06 11:32:04,122: INFO: common : created directory at: artifacts/data_ingestion]
[2025-09-06 11:32:05,395: INFO: data_ingestion : artifacts/data_ingestion/data.zip download! with following info: 
Connection: close
Content-Length: 23329
Cache-Control: max-age=300
Content-Security-Policy: default-src 'none'; style-src 'unsafe-inline'; sandbox
Content-Type: application/zip
ETag: "c69888a4ae59bc5a893392785a938ccd4937981c06ba8a9d6a21aa52b4ab5b6e"
Strict-Transport-Security: max-age=31536000
X-Content-Type-Options: nosniff
X-Frame-Options: deny
X-XSS-Protection: 1; mode=block
X-GitHub-Request-Id: EEC2:220E79:5C098:11E6BC:68BBCE5C
Accept-Ranges: bytes
Date: Sat, 06 Sep 2025 06:02:05 GMT
Via: 1.1 varnish
X-Served-By: cache-ccu830042-CCU
X-Cache: MISS
X-Cache-Hits: 0
X-Timer: S1757138525.254084,VS0,VE298
Vary: Authorization,Accept-Encoding
Access-Control-Allow-Origin: *
Cross-Origin-Resource-Policy: cross-origin
X-Fastly-Request-ID: 29e37cd92db2f10badbabd2c2cece01db7fa2f96
Expires: Sat, 06 Sep 2025 06:07:05 GMT
Source-Age: 0

]
[2025-09-06 11:32:05,523: INFO: main : >>>>>> stage Data Ingestion stage completed <<<<<<

x==========x]
[2025-09-06 11:32:05,524: INFO: main : >>>>>> stage Data Validation stage started <<<<<<]
[2025-09-06 11:32:05,541: INFO: common : created directory at: artifacts]
[2025-09-06 11:32:05,543: INFO: common : created directory at: artifacts/data_validation]
[2025-09-06 11:32:05,566: INFO: main : >>>>>> stage Data Validation stage completed <<<<<<

x==========x]
[2025-09-06 11:32:05,566: INFO: main : >>>>>> stage Data Transformation stage started <<<<<<]
[2025-09-06 11:32:05,578: INFO: common : created directory at: artifacts]
[2025-09-06 11:32:05,579: INFO: common : created directory at: artifacts/data_transformation]
[2025-09-06 11:32:05,627: INFO: data_transformation : Splited data into training and test sets]
[2025-09-06 11:32:05,627: INFO: data_transformation : (1199, 12)]
[2025-09-06 11:32:05,628: INFO: data_transformation : (400, 12)]
[2025-09-06 11:32:05,628: INFO: main : >>>>>> stage Data Transformation stage completed <<<<<<

x==========x]
[2025-09-06 11:32:05,628: INFO: main : >>>>>> stage Model Training stage started <<<<<<]
[2025-09-06 11:32:05,634: INFO: common : created directory at: artifacts]
[2025-09-06 11:32:05,634: INFO: common : created directory at: artifacts/model_trainer]
[2025-09-06 11:32:05,702: INFO: main : >>>>>> stage Model Training stage completed <<<<<<

x==========x]
[2025-09-06 11:32:05,703: INFO: main : >>>>>> stage Model Evaluation stage started <<<<<<]
[2025-09-06 11:32:05,710: INFO: common : created directory at: artifacts]
[2025-09-06 11:32:05,711: INFO: common : created directory at: artifacts/model_evaluation]
[2025-09-06 11:32:07,819: ERROR: main : API request to endpoint /api/2.0/mlflow/runs/create failed with error code 404 != 200. Response body: '']
Traceback (most recent call last):
  File "D:\data science and AI\2. MLOPS COURSE BY KRISH\14. First Project\byme\datascineceproject\main.py", line 54, in <module>
    obj.intitate_model_evaluation_pipeline()
  File "D:\data science and AI\2. MLOPS COURSE BY KRISH\14. First Project\byme\datascineceproject\src\datascience\pipeline\model_evaluation_pipeline.py", line 14, in intitate_model_evaluation_pipeline
    model_evaluation.log_into_mlflow()
  File "D:\data science and AI\2. MLOPS COURSE BY KRISH\14. First Project\byme\datascineceproject\src\datascience\components\model_evaluation.py", line 34, in log_into_mlflow
    with mlflow.start_run():
         ^^^^^^^^^^^^^^^^^^
  File "C:\Users\hp\anaconda3\Lib\site-packages\mlflow\tracking\fluent.py", line 474, in start_run
    active_run_obj = client.create_run(
                     ^^^^^^^^^^^^^^^^^^
  File "C:\Users\hp\anaconda3\Lib\site-packages\mlflow\tracking\client.py", line 435, in create_run
    return self._tracking_client.create_run(experiment_id, start_time, tags, run_name)
           ^^^^^^^^^^^^^^^^^^^^^^^^^^^^^^^^^^^^^^^^^^^^^^^^^^^^^^^^^^^^^^^^^^^^^^^^^^^
  File "C:\Users\hp\anaconda3\Lib\site-packages\mlflow\tracking\_tracking_service\client.py", line 161, in create_run
    return self.store.create_run(
           ^^^^^^^^^^^^^^^^^^^^^^
  File "C:\Users\hp\anaconda3\Lib\site-packages\mlflow\store\tracking\rest_store.py", line 272, in create_run
    response_proto = self._call_endpoint(CreateRun, req_body)
                     ^^^^^^^^^^^^^^^^^^^^^^^^^^^^^^^^^^^^^^^^
  File "C:\Users\hp\anaconda3\Lib\site-packages\mlflow\store\tracking\rest_store.py", line 135, in _call_endpoint
    return call_endpoint(
           ^^^^^^^^^^^^^^
  File "C:\Users\hp\anaconda3\Lib\site-packages\mlflow\utils\rest_utils.py", line 590, in call_endpoint
    response = verify_rest_response(response, endpoint)
               ^^^^^^^^^^^^^^^^^^^^^^^^^^^^^^^^^^^^^^^^
  File "C:\Users\hp\anaconda3\Lib\site-packages\mlflow\utils\rest_utils.py", line 310, in verify_rest_response
    raise MlflowException(
mlflow.exceptions.MlflowException: API request to endpoint /api/2.0/mlflow/runs/create failed with error code 404 != 200. Response body: ''
[2025-09-06 11:37:34,278: INFO: common : created directory at: artifacts]
[2025-09-06 11:37:34,281: INFO: common : created directory at: artifacts/model_evaluation]
[2025-09-06 11:40:09,795: INFO: common : created directory at: artifacts]
[2025-09-06 11:40:09,798: INFO: common : created directory at: artifacts/model_evaluation]
[2025-09-06 11:40:10,330: INFO: common : json file saved at: artifacts\model_evaluation\metrics.json]
[2025-09-06 11:41:51,638: INFO: common : created directory at: artifacts]
[2025-09-06 11:41:51,640: INFO: common : created directory at: artifacts/model_evaluation]
[2025-09-06 11:41:52,131: INFO: common : json file saved at: artifacts\model_evaluation\metrics.json]
[2025-09-06 12:02:21,830: INFO: utils : NumExpr defaulting to 8 threads.]
[2025-09-06 12:02:27,735: INFO: main : >>>>>> stage Data Ingestion stage started <<<<<<]
[2025-09-06 12:02:27,742: INFO: common : created directory at: artifacts]
[2025-09-06 12:02:27,743: INFO: common : created directory at: artifacts/data_ingestion]
[2025-09-06 12:02:27,744: INFO: data_ingestion : File already exists]
[2025-09-06 12:02:27,747: INFO: main : >>>>>> stage Data Ingestion stage completed <<<<<<

x==========x]
[2025-09-06 12:02:27,747: INFO: main : >>>>>> stage Data Validation stage started <<<<<<]
[2025-09-06 12:02:27,753: INFO: common : created directory at: artifacts]
[2025-09-06 12:02:27,753: INFO: common : created directory at: artifacts/data_validation]
[2025-09-06 12:02:27,761: INFO: main : >>>>>> stage Data Validation stage completed <<<<<<

x==========x]
[2025-09-06 12:02:27,762: INFO: main : >>>>>> stage Data Transformation stage started <<<<<<]
[2025-09-06 12:02:27,768: INFO: common : created directory at: artifacts]
[2025-09-06 12:02:27,769: INFO: common : created directory at: artifacts/data_transformation]
[2025-09-06 12:02:27,818: INFO: data_transformation : Splited data into training and test sets]
[2025-09-06 12:02:27,818: INFO: data_transformation : (1199, 12)]
[2025-09-06 12:02:27,818: INFO: data_transformation : (400, 12)]
[2025-09-06 12:02:27,818: INFO: main : >>>>>> stage Data Transformation stage completed <<<<<<

x==========x]
[2025-09-06 12:02:27,819: INFO: main : >>>>>> stage Model Training stage started <<<<<<]
[2025-09-06 12:02:27,825: INFO: common : created directory at: artifacts]
[2025-09-06 12:02:27,826: INFO: common : created directory at: artifacts/model_trainer]
[2025-09-06 12:02:27,884: INFO: main : >>>>>> stage Model Training stage completed <<<<<<

x==========x]
[2025-09-06 12:02:27,884: INFO: main : >>>>>> stage Model Evaluation stage started <<<<<<]
[2025-09-06 12:02:27,891: INFO: common : created directory at: artifacts]
[2025-09-06 12:02:27,894: INFO: common : created directory at: artifacts/model_evaluation]
[2025-09-06 12:02:29,851: ERROR: main : API request to endpoint /api/2.0/mlflow/runs/create failed with error code 403 != 200. Response body: '']
Traceback (most recent call last):
  File "D:\data science and AI\2. MLOPS COURSE BY KRISH\14. First Project\byme\datascineceproject\main.py", line 54, in <module>
    obj.intitate_model_evaluation_pipeline()
  File "D:\data science and AI\2. MLOPS COURSE BY KRISH\14. First Project\byme\datascineceproject\src\datascience\pipeline\model_evaluation_pipeline.py", line 14, in intitate_model_evaluation_pipeline
    model_evaluation.log_into_mlflow()
  File "D:\data science and AI\2. MLOPS COURSE BY KRISH\14. First Project\byme\datascineceproject\src\datascience\components\model_evaluation.py", line 35, in log_into_mlflow
    with mlflow.start_run():
         ^^^^^^^^^^^^^^^^^^
  File "C:\Users\hp\anaconda3\Lib\site-packages\mlflow\tracking\fluent.py", line 474, in start_run
    active_run_obj = client.create_run(
                     ^^^^^^^^^^^^^^^^^^
  File "C:\Users\hp\anaconda3\Lib\site-packages\mlflow\tracking\client.py", line 435, in create_run
    return self._tracking_client.create_run(experiment_id, start_time, tags, run_name)
           ^^^^^^^^^^^^^^^^^^^^^^^^^^^^^^^^^^^^^^^^^^^^^^^^^^^^^^^^^^^^^^^^^^^^^^^^^^^
  File "C:\Users\hp\anaconda3\Lib\site-packages\mlflow\tracking\_tracking_service\client.py", line 161, in create_run
    return self.store.create_run(
           ^^^^^^^^^^^^^^^^^^^^^^
  File "C:\Users\hp\anaconda3\Lib\site-packages\mlflow\store\tracking\rest_store.py", line 272, in create_run
    response_proto = self._call_endpoint(CreateRun, req_body)
                     ^^^^^^^^^^^^^^^^^^^^^^^^^^^^^^^^^^^^^^^^
  File "C:\Users\hp\anaconda3\Lib\site-packages\mlflow\store\tracking\rest_store.py", line 135, in _call_endpoint
    return call_endpoint(
           ^^^^^^^^^^^^^^
  File "C:\Users\hp\anaconda3\Lib\site-packages\mlflow\utils\rest_utils.py", line 590, in call_endpoint
    response = verify_rest_response(response, endpoint)
               ^^^^^^^^^^^^^^^^^^^^^^^^^^^^^^^^^^^^^^^^
  File "C:\Users\hp\anaconda3\Lib\site-packages\mlflow\utils\rest_utils.py", line 310, in verify_rest_response
    raise MlflowException(
mlflow.exceptions.MlflowException: API request to endpoint /api/2.0/mlflow/runs/create failed with error code 403 != 200. Response body: ''
[2025-09-06 12:04:31,116: INFO: utils : NumExpr defaulting to 8 threads.]
[2025-09-06 12:04:35,961: INFO: main : >>>>>> stage Data Ingestion stage started <<<<<<]
[2025-09-06 12:04:35,970: INFO: common : created directory at: artifacts]
[2025-09-06 12:04:35,970: INFO: common : created directory at: artifacts/data_ingestion]
[2025-09-06 12:04:35,971: INFO: data_ingestion : File already exists]
[2025-09-06 12:04:35,976: INFO: main : >>>>>> stage Data Ingestion stage completed <<<<<<

x==========x]
[2025-09-06 12:04:35,976: INFO: main : >>>>>> stage Data Validation stage started <<<<<<]
[2025-09-06 12:04:35,980: INFO: common : created directory at: artifacts]
[2025-09-06 12:04:35,982: INFO: common : created directory at: artifacts/data_validation]
[2025-09-06 12:04:35,989: INFO: main : >>>>>> stage Data Validation stage completed <<<<<<

x==========x]
[2025-09-06 12:04:35,990: INFO: main : >>>>>> stage Data Transformation stage started <<<<<<]
[2025-09-06 12:04:35,998: INFO: common : created directory at: artifacts]
[2025-09-06 12:04:36,000: INFO: common : created directory at: artifacts/data_transformation]
[2025-09-06 12:04:36,052: INFO: data_transformation : Splited data into training and test sets]
[2025-09-06 12:04:36,052: INFO: data_transformation : (1199, 12)]
[2025-09-06 12:04:36,052: INFO: data_transformation : (400, 12)]
[2025-09-06 12:04:36,052: INFO: main : >>>>>> stage Data Transformation stage completed <<<<<<

x==========x]
[2025-09-06 12:04:36,053: INFO: main : >>>>>> stage Model Training stage started <<<<<<]
[2025-09-06 12:04:36,061: INFO: common : created directory at: artifacts]
[2025-09-06 12:04:36,061: INFO: common : created directory at: artifacts/model_trainer]
[2025-09-06 12:04:36,117: INFO: main : >>>>>> stage Model Training stage completed <<<<<<

x==========x]
[2025-09-06 12:04:36,117: INFO: main : >>>>>> stage Model Evaluation stage started <<<<<<]
[2025-09-06 12:04:36,123: INFO: common : created directory at: artifacts]
[2025-09-06 12:04:36,123: INFO: common : created directory at: artifacts/model_evaluation]
[2025-09-06 12:04:37,850: ERROR: main : API request to endpoint /api/2.0/mlflow/runs/create failed with error code 403 != 200. Response body: '']
Traceback (most recent call last):
  File "D:\data science and AI\2. MLOPS COURSE BY KRISH\14. First Project\byme\datascineceproject\main.py", line 54, in <module>
    obj.intitate_model_evaluation_pipeline()
  File "D:\data science and AI\2. MLOPS COURSE BY KRISH\14. First Project\byme\datascineceproject\src\datascience\pipeline\model_evaluation_pipeline.py", line 14, in intitate_model_evaluation_pipeline
    model_evaluation.log_into_mlflow()
  File "D:\data science and AI\2. MLOPS COURSE BY KRISH\14. First Project\byme\datascineceproject\src\datascience\components\model_evaluation.py", line 35, in log_into_mlflow
    with mlflow.start_run():
         ^^^^^^^^^^^^^^^^^^
  File "C:\Users\hp\anaconda3\Lib\site-packages\mlflow\tracking\fluent.py", line 474, in start_run
    active_run_obj = client.create_run(
                     ^^^^^^^^^^^^^^^^^^
  File "C:\Users\hp\anaconda3\Lib\site-packages\mlflow\tracking\client.py", line 435, in create_run
    return self._tracking_client.create_run(experiment_id, start_time, tags, run_name)
           ^^^^^^^^^^^^^^^^^^^^^^^^^^^^^^^^^^^^^^^^^^^^^^^^^^^^^^^^^^^^^^^^^^^^^^^^^^^
  File "C:\Users\hp\anaconda3\Lib\site-packages\mlflow\tracking\_tracking_service\client.py", line 161, in create_run
    return self.store.create_run(
           ^^^^^^^^^^^^^^^^^^^^^^
  File "C:\Users\hp\anaconda3\Lib\site-packages\mlflow\store\tracking\rest_store.py", line 272, in create_run
    response_proto = self._call_endpoint(CreateRun, req_body)
                     ^^^^^^^^^^^^^^^^^^^^^^^^^^^^^^^^^^^^^^^^
  File "C:\Users\hp\anaconda3\Lib\site-packages\mlflow\store\tracking\rest_store.py", line 135, in _call_endpoint
    return call_endpoint(
           ^^^^^^^^^^^^^^
  File "C:\Users\hp\anaconda3\Lib\site-packages\mlflow\utils\rest_utils.py", line 590, in call_endpoint
    response = verify_rest_response(response, endpoint)
               ^^^^^^^^^^^^^^^^^^^^^^^^^^^^^^^^^^^^^^^^
  File "C:\Users\hp\anaconda3\Lib\site-packages\mlflow\utils\rest_utils.py", line 310, in verify_rest_response
    raise MlflowException(
mlflow.exceptions.MlflowException: API request to endpoint /api/2.0/mlflow/runs/create failed with error code 403 != 200. Response body: ''
[2025-09-06 12:09:01,510: INFO: utils : NumExpr defaulting to 8 threads.]
[2025-09-06 12:09:06,634: INFO: main : >>>>>> stage Data Ingestion stage started <<<<<<]
[2025-09-06 12:09:06,641: INFO: common : created directory at: artifacts]
[2025-09-06 12:09:06,642: INFO: common : created directory at: artifacts/data_ingestion]
[2025-09-06 12:09:06,642: INFO: data_ingestion : File already exists]
[2025-09-06 12:09:06,644: INFO: main : >>>>>> stage Data Ingestion stage completed <<<<<<

x==========x]
[2025-09-06 12:09:06,645: INFO: main : >>>>>> stage Data Validation stage started <<<<<<]
[2025-09-06 12:09:06,651: INFO: common : created directory at: artifacts]
[2025-09-06 12:09:06,651: INFO: common : created directory at: artifacts/data_validation]
[2025-09-06 12:09:06,659: INFO: main : >>>>>> stage Data Validation stage completed <<<<<<

x==========x]
[2025-09-06 12:09:06,660: INFO: main : >>>>>> stage Data Transformation stage started <<<<<<]
[2025-09-06 12:09:06,666: INFO: common : created directory at: artifacts]
[2025-09-06 12:09:06,667: INFO: common : created directory at: artifacts/data_transformation]
[2025-09-06 12:09:06,717: INFO: data_transformation : Splited data into training and test sets]
[2025-09-06 12:09:06,717: INFO: data_transformation : (1199, 12)]
[2025-09-06 12:09:06,718: INFO: data_transformation : (400, 12)]
[2025-09-06 12:09:06,719: INFO: main : >>>>>> stage Data Transformation stage completed <<<<<<

x==========x]
[2025-09-06 12:09:06,719: INFO: main : >>>>>> stage Model Training stage started <<<<<<]
[2025-09-06 12:09:06,726: INFO: common : created directory at: artifacts]
[2025-09-06 12:09:06,727: INFO: common : created directory at: artifacts/model_trainer]
[2025-09-06 12:09:06,779: INFO: main : >>>>>> stage Model Training stage completed <<<<<<

x==========x]
[2025-09-06 12:09:06,780: INFO: main : >>>>>> stage Model Evaluation stage started <<<<<<]
[2025-09-06 12:09:06,787: INFO: common : created directory at: artifacts]
[2025-09-06 12:09:06,788: INFO: common : created directory at: artifacts/model_evaluation]
[2025-09-06 12:09:08,489: INFO: common : json file saved at: artifacts\model_evaluation\metrics.json]
[2025-09-06 12:09:15,342: ERROR: main : INTERNAL_ERROR: Response: {'error': 'unsupported endpoint, please contact support@dagshub.com'}]
Traceback (most recent call last):
  File "D:\data science and AI\2. MLOPS COURSE BY KRISH\14. First Project\byme\datascineceproject\src\datascience\components\model_evaluation.py", line 52, in log_into_mlflow
    mlflow.sklearn.log_model(
  File "C:\Users\hp\anaconda3\Lib\site-packages\mlflow\sklearn\__init__.py", line 426, in log_model
    return Model.log(
           ^^^^^^^^^^
  File "C:\Users\hp\anaconda3\Lib\site-packages\mlflow\models\model.py", line 1161, in log
    model = mlflow.initialize_logged_model(
            ^^^^^^^^^^^^^^^^^^^^^^^^^^^^^^^
  File "C:\Users\hp\anaconda3\Lib\site-packages\mlflow\tracking\fluent.py", line 2130, in initialize_logged_model
    model = _create_logged_model(
            ^^^^^^^^^^^^^^^^^^^^^
  File "C:\Users\hp\anaconda3\Lib\site-packages\mlflow\tracking\fluent.py", line 2257, in _create_logged_model
    return MlflowClient().create_logged_model(
           ^^^^^^^^^^^^^^^^^^^^^^^^^^^^^^^^^^^
  File "C:\Users\hp\anaconda3\Lib\site-packages\mlflow\tracking\client.py", line 5371, in create_logged_model
    return self._tracking_client.create_logged_model(
           ^^^^^^^^^^^^^^^^^^^^^^^^^^^^^^^^^^^^^^^^^^
  File "C:\Users\hp\anaconda3\Lib\site-packages\mlflow\tracking\_tracking_service\client.py", line 824, in create_logged_model
    return self.store.create_logged_model(
           ^^^^^^^^^^^^^^^^^^^^^^^^^^^^^^^
  File "C:\Users\hp\anaconda3\Lib\site-packages\mlflow\store\tracking\rest_store.py", line 936, in create_logged_model
    response_proto = self._call_endpoint(CreateLoggedModel, req_body)
                     ^^^^^^^^^^^^^^^^^^^^^^^^^^^^^^^^^^^^^^^^^^^^^^^^
  File "C:\Users\hp\anaconda3\Lib\site-packages\mlflow\store\tracking\rest_store.py", line 135, in _call_endpoint
    return call_endpoint(
           ^^^^^^^^^^^^^^
  File "C:\Users\hp\anaconda3\Lib\site-packages\mlflow\utils\rest_utils.py", line 590, in call_endpoint
    response = verify_rest_response(response, endpoint)
               ^^^^^^^^^^^^^^^^^^^^^^^^^^^^^^^^^^^^^^^^
  File "C:\Users\hp\anaconda3\Lib\site-packages\mlflow\utils\rest_utils.py", line 304, in verify_rest_response
    raise RestException(json.loads(response.text))
mlflow.exceptions.RestException: INTERNAL_ERROR: Response: {'error': 'unsupported endpoint, please contact support@dagshub.com'}

During handling of the above exception, another exception occurred:

Traceback (most recent call last):
  File "D:\data science and AI\2. MLOPS COURSE BY KRISH\14. First Project\byme\datascineceproject\main.py", line 54, in <module>
    obj.intitate_model_evaluation_pipeline()
  File "D:\data science and AI\2. MLOPS COURSE BY KRISH\14. First Project\byme\datascineceproject\src\datascience\pipeline\model_evaluation_pipeline.py", line 14, in intitate_model_evaluation_pipeline
    model_evaluation.log_into_mlflow()
  File "D:\data science and AI\2. MLOPS COURSE BY KRISH\14. First Project\byme\datascineceproject\src\datascience\components\model_evaluation.py", line 60, in log_into_mlflow
    mlflow.sklearn.log_model(model, "model")
  File "C:\Users\hp\anaconda3\Lib\site-packages\mlflow\sklearn\__init__.py", line 426, in log_model
    return Model.log(
           ^^^^^^^^^^
  File "C:\Users\hp\anaconda3\Lib\site-packages\mlflow\models\model.py", line 1161, in log
    model = mlflow.initialize_logged_model(
            ^^^^^^^^^^^^^^^^^^^^^^^^^^^^^^^
  File "C:\Users\hp\anaconda3\Lib\site-packages\mlflow\tracking\fluent.py", line 2130, in initialize_logged_model
    model = _create_logged_model(
            ^^^^^^^^^^^^^^^^^^^^^
  File "C:\Users\hp\anaconda3\Lib\site-packages\mlflow\tracking\fluent.py", line 2257, in _create_logged_model
    return MlflowClient().create_logged_model(
           ^^^^^^^^^^^^^^^^^^^^^^^^^^^^^^^^^^^
  File "C:\Users\hp\anaconda3\Lib\site-packages\mlflow\tracking\client.py", line 5371, in create_logged_model
    return self._tracking_client.create_logged_model(
           ^^^^^^^^^^^^^^^^^^^^^^^^^^^^^^^^^^^^^^^^^^
  File "C:\Users\hp\anaconda3\Lib\site-packages\mlflow\tracking\_tracking_service\client.py", line 824, in create_logged_model
    return self.store.create_logged_model(
           ^^^^^^^^^^^^^^^^^^^^^^^^^^^^^^^
  File "C:\Users\hp\anaconda3\Lib\site-packages\mlflow\store\tracking\rest_store.py", line 936, in create_logged_model
    response_proto = self._call_endpoint(CreateLoggedModel, req_body)
                     ^^^^^^^^^^^^^^^^^^^^^^^^^^^^^^^^^^^^^^^^^^^^^^^^
  File "C:\Users\hp\anaconda3\Lib\site-packages\mlflow\store\tracking\rest_store.py", line 135, in _call_endpoint
    return call_endpoint(
           ^^^^^^^^^^^^^^
  File "C:\Users\hp\anaconda3\Lib\site-packages\mlflow\utils\rest_utils.py", line 590, in call_endpoint
    response = verify_rest_response(response, endpoint)
               ^^^^^^^^^^^^^^^^^^^^^^^^^^^^^^^^^^^^^^^^
  File "C:\Users\hp\anaconda3\Lib\site-packages\mlflow\utils\rest_utils.py", line 304, in verify_rest_response
    raise RestException(json.loads(response.text))
mlflow.exceptions.RestException: INTERNAL_ERROR: Response: {'error': 'unsupported endpoint, please contact support@dagshub.com'}
[2025-09-06 12:09:55,604: INFO: utils : NumExpr defaulting to 8 threads.]
[2025-09-06 12:10:00,922: INFO: main : >>>>>> stage Data Ingestion stage started <<<<<<]
[2025-09-06 12:10:00,926: INFO: common : created directory at: artifacts]
[2025-09-06 12:10:00,927: INFO: common : created directory at: artifacts/data_ingestion]
[2025-09-06 12:10:00,927: INFO: data_ingestion : File already exists]
[2025-09-06 12:10:00,929: INFO: main : >>>>>> stage Data Ingestion stage completed <<<<<<

x==========x]
[2025-09-06 12:10:00,930: INFO: main : >>>>>> stage Data Validation stage started <<<<<<]
[2025-09-06 12:10:00,938: INFO: common : created directory at: artifacts]
[2025-09-06 12:10:00,939: INFO: common : created directory at: artifacts/data_validation]
[2025-09-06 12:10:00,949: INFO: main : >>>>>> stage Data Validation stage completed <<<<<<

x==========x]
[2025-09-06 12:10:00,949: INFO: main : >>>>>> stage Data Transformation stage started <<<<<<]
[2025-09-06 12:10:00,957: INFO: common : created directory at: artifacts]
[2025-09-06 12:10:00,958: INFO: common : created directory at: artifacts/data_transformation]
[2025-09-06 12:10:00,993: INFO: data_transformation : Splited data into training and test sets]
[2025-09-06 12:10:00,993: INFO: data_transformation : (1199, 12)]
[2025-09-06 12:10:00,994: INFO: data_transformation : (400, 12)]
[2025-09-06 12:10:00,995: INFO: main : >>>>>> stage Data Transformation stage completed <<<<<<

x==========x]
[2025-09-06 12:10:00,995: INFO: main : >>>>>> stage Model Training stage started <<<<<<]
[2025-09-06 12:10:01,001: INFO: common : created directory at: artifacts]
[2025-09-06 12:10:01,002: INFO: common : created directory at: artifacts/model_trainer]
[2025-09-06 12:10:01,044: INFO: main : >>>>>> stage Model Training stage completed <<<<<<

x==========x]
[2025-09-06 12:10:01,044: INFO: main : >>>>>> stage Model Evaluation stage started <<<<<<]
[2025-09-06 12:10:01,051: INFO: common : created directory at: artifacts]
[2025-09-06 12:10:01,051: INFO: common : created directory at: artifacts/model_evaluation]
[2025-09-06 12:10:02,707: WARNING: connectionpool : Retrying (Retry(total=6, connect=6, read=7, redirect=7, status=7)) after connection broken by 'NameResolutionError("<urllib3.connection.HTTPSConnection object at 0x00000233E358F530>: Failed to resolve 'dagshub.com' ([Errno 11001] getaddrinfo failed)")': /Sip4818/datascineceproject.mlflow/api/2.0/mlflow/runs/create]
[2025-09-06 12:10:48,714: WARNING: connectionpool : Retrying (Retry(total=5, connect=5, read=7, redirect=7, status=7)) after connection broken by 'NameResolutionError("<urllib3.connection.HTTPSConnection object at 0x00000233E45BCA10>: Failed to resolve 'dagshub.com' ([Errno 11001] getaddrinfo failed)")': /Sip4818/datascineceproject.mlflow/api/2.0/mlflow/runs/create]
[2025-09-06 12:10:57,186: WARNING: connectionpool : Retrying (Retry(total=4, connect=4, read=7, redirect=7, status=7)) after connection broken by 'NameResolutionError("<urllib3.connection.HTTPSConnection object at 0x00000233E45BCB60>: Failed to resolve 'dagshub.com' ([Errno 11001] getaddrinfo failed)")': /Sip4818/datascineceproject.mlflow/api/2.0/mlflow/runs/create]
[2025-09-06 12:11:27,380: WARNING: connectionpool : Retrying (Retry(total=3, connect=3, read=7, redirect=7, status=7)) after connection broken by 'NewConnectionError('<urllib3.connection.HTTPSConnection object at 0x00000233E45BCCB0>: Failed to establish a new connection: [WinError 10053] An established connection was aborted by the software in your host machine')': /Sip4818/datascineceproject.mlflow/api/2.0/mlflow/runs/create]
[2025-09-06 12:11:28,043: INFO: common : json file saved at: artifacts\model_evaluation\metrics.json]
[2025-09-06 12:11:35,321: ERROR: main : INTERNAL_ERROR: Response: {'error': 'unsupported endpoint, please contact support@dagshub.com'}]
Traceback (most recent call last):
  File "D:\data science and AI\2. MLOPS COURSE BY KRISH\14. First Project\byme\datascineceproject\src\datascience\components\model_evaluation.py", line 52, in log_into_mlflow
    mlflow.sklearn.log_model(
  File "C:\Users\hp\anaconda3\Lib\site-packages\mlflow\sklearn\__init__.py", line 426, in log_model
    return Model.log(
           ^^^^^^^^^^
  File "C:\Users\hp\anaconda3\Lib\site-packages\mlflow\models\model.py", line 1161, in log
    model = mlflow.initialize_logged_model(
            ^^^^^^^^^^^^^^^^^^^^^^^^^^^^^^^
  File "C:\Users\hp\anaconda3\Lib\site-packages\mlflow\tracking\fluent.py", line 2130, in initialize_logged_model
    model = _create_logged_model(
            ^^^^^^^^^^^^^^^^^^^^^
  File "C:\Users\hp\anaconda3\Lib\site-packages\mlflow\tracking\fluent.py", line 2257, in _create_logged_model
    return MlflowClient().create_logged_model(
           ^^^^^^^^^^^^^^^^^^^^^^^^^^^^^^^^^^^
  File "C:\Users\hp\anaconda3\Lib\site-packages\mlflow\tracking\client.py", line 5371, in create_logged_model
    return self._tracking_client.create_logged_model(
           ^^^^^^^^^^^^^^^^^^^^^^^^^^^^^^^^^^^^^^^^^^
  File "C:\Users\hp\anaconda3\Lib\site-packages\mlflow\tracking\_tracking_service\client.py", line 824, in create_logged_model
    return self.store.create_logged_model(
           ^^^^^^^^^^^^^^^^^^^^^^^^^^^^^^^
  File "C:\Users\hp\anaconda3\Lib\site-packages\mlflow\store\tracking\rest_store.py", line 936, in create_logged_model
    response_proto = self._call_endpoint(CreateLoggedModel, req_body)
                     ^^^^^^^^^^^^^^^^^^^^^^^^^^^^^^^^^^^^^^^^^^^^^^^^
  File "C:\Users\hp\anaconda3\Lib\site-packages\mlflow\store\tracking\rest_store.py", line 135, in _call_endpoint
    return call_endpoint(
           ^^^^^^^^^^^^^^
  File "C:\Users\hp\anaconda3\Lib\site-packages\mlflow\utils\rest_utils.py", line 590, in call_endpoint
    response = verify_rest_response(response, endpoint)
               ^^^^^^^^^^^^^^^^^^^^^^^^^^^^^^^^^^^^^^^^
  File "C:\Users\hp\anaconda3\Lib\site-packages\mlflow\utils\rest_utils.py", line 304, in verify_rest_response
    raise RestException(json.loads(response.text))
mlflow.exceptions.RestException: INTERNAL_ERROR: Response: {'error': 'unsupported endpoint, please contact support@dagshub.com'}

During handling of the above exception, another exception occurred:

Traceback (most recent call last):
  File "D:\data science and AI\2. MLOPS COURSE BY KRISH\14. First Project\byme\datascineceproject\main.py", line 54, in <module>
    obj.intitate_model_evaluation_pipeline()
  File "D:\data science and AI\2. MLOPS COURSE BY KRISH\14. First Project\byme\datascineceproject\src\datascience\pipeline\model_evaluation_pipeline.py", line 14, in intitate_model_evaluation_pipeline
    model_evaluation.log_into_mlflow()
  File "D:\data science and AI\2. MLOPS COURSE BY KRISH\14. First Project\byme\datascineceproject\src\datascience\components\model_evaluation.py", line 60, in log_into_mlflow
    mlflow.sklearn.log_model(model, "model")
  File "C:\Users\hp\anaconda3\Lib\site-packages\mlflow\sklearn\__init__.py", line 426, in log_model
    return Model.log(
           ^^^^^^^^^^
  File "C:\Users\hp\anaconda3\Lib\site-packages\mlflow\models\model.py", line 1161, in log
    model = mlflow.initialize_logged_model(
            ^^^^^^^^^^^^^^^^^^^^^^^^^^^^^^^
  File "C:\Users\hp\anaconda3\Lib\site-packages\mlflow\tracking\fluent.py", line 2130, in initialize_logged_model
    model = _create_logged_model(
            ^^^^^^^^^^^^^^^^^^^^^
  File "C:\Users\hp\anaconda3\Lib\site-packages\mlflow\tracking\fluent.py", line 2257, in _create_logged_model
    return MlflowClient().create_logged_model(
           ^^^^^^^^^^^^^^^^^^^^^^^^^^^^^^^^^^^
  File "C:\Users\hp\anaconda3\Lib\site-packages\mlflow\tracking\client.py", line 5371, in create_logged_model
    return self._tracking_client.create_logged_model(
           ^^^^^^^^^^^^^^^^^^^^^^^^^^^^^^^^^^^^^^^^^^
  File "C:\Users\hp\anaconda3\Lib\site-packages\mlflow\tracking\_tracking_service\client.py", line 824, in create_logged_model
    return self.store.create_logged_model(
           ^^^^^^^^^^^^^^^^^^^^^^^^^^^^^^^
  File "C:\Users\hp\anaconda3\Lib\site-packages\mlflow\store\tracking\rest_store.py", line 936, in create_logged_model
    response_proto = self._call_endpoint(CreateLoggedModel, req_body)
                     ^^^^^^^^^^^^^^^^^^^^^^^^^^^^^^^^^^^^^^^^^^^^^^^^
  File "C:\Users\hp\anaconda3\Lib\site-packages\mlflow\store\tracking\rest_store.py", line 135, in _call_endpoint
    return call_endpoint(
           ^^^^^^^^^^^^^^
  File "C:\Users\hp\anaconda3\Lib\site-packages\mlflow\utils\rest_utils.py", line 590, in call_endpoint
    response = verify_rest_response(response, endpoint)
               ^^^^^^^^^^^^^^^^^^^^^^^^^^^^^^^^^^^^^^^^
  File "C:\Users\hp\anaconda3\Lib\site-packages\mlflow\utils\rest_utils.py", line 304, in verify_rest_response
    raise RestException(json.loads(response.text))
mlflow.exceptions.RestException: INTERNAL_ERROR: Response: {'error': 'unsupported endpoint, please contact support@dagshub.com'}
[2025-09-06 12:12:00,893: INFO: utils : NumExpr defaulting to 8 threads.]
[2025-09-06 12:12:04,372: INFO: main : >>>>>> stage Data Ingestion stage started <<<<<<]
[2025-09-06 12:12:04,469: INFO: common : created directory at: artifacts]
[2025-09-06 12:12:04,469: INFO: common : created directory at: artifacts/data_ingestion]
[2025-09-06 12:12:04,470: INFO: data_ingestion : File already exists]
[2025-09-06 12:12:04,480: INFO: main : >>>>>> stage Data Ingestion stage completed <<<<<<

x==========x]
[2025-09-06 12:12:04,481: INFO: main : >>>>>> stage Data Validation stage started <<<<<<]
[2025-09-06 12:12:04,486: INFO: common : created directory at: artifacts]
[2025-09-06 12:12:04,487: INFO: common : created directory at: artifacts/data_validation]
[2025-09-06 12:12:04,494: INFO: main : >>>>>> stage Data Validation stage completed <<<<<<

x==========x]
[2025-09-06 12:12:04,495: INFO: main : >>>>>> stage Data Transformation stage started <<<<<<]
[2025-09-06 12:12:04,499: INFO: common : created directory at: artifacts]
[2025-09-06 12:12:04,501: INFO: common : created directory at: artifacts/data_transformation]
[2025-09-06 12:12:04,527: INFO: data_transformation : Splited data into training and test sets]
[2025-09-06 12:12:04,527: INFO: data_transformation : (1199, 12)]
[2025-09-06 12:12:04,528: INFO: data_transformation : (400, 12)]
[2025-09-06 12:12:04,528: INFO: main : >>>>>> stage Data Transformation stage completed <<<<<<

x==========x]
[2025-09-06 12:12:04,528: INFO: main : >>>>>> stage Model Training stage started <<<<<<]
[2025-09-06 12:12:04,533: INFO: common : created directory at: artifacts]
[2025-09-06 12:12:04,533: INFO: common : created directory at: artifacts/model_trainer]
[2025-09-06 12:12:04,561: INFO: main : >>>>>> stage Model Training stage completed <<<<<<

x==========x]
[2025-09-06 12:12:04,561: INFO: main : >>>>>> stage Model Evaluation stage started <<<<<<]
[2025-09-06 12:12:04,566: INFO: common : created directory at: artifacts]
[2025-09-06 12:12:04,567: INFO: common : created directory at: artifacts/model_evaluation]
[2025-09-06 12:12:05,964: INFO: common : json file saved at: artifacts\model_evaluation\metrics.json]
[2025-09-06 12:12:12,442: ERROR: main : INTERNAL_ERROR: Response: {'error': 'unsupported endpoint, please contact support@dagshub.com'}]
Traceback (most recent call last):
  File "D:\data science and AI\2. MLOPS COURSE BY KRISH\14. First Project\byme\datascineceproject\src\datascience\components\model_evaluation.py", line 52, in log_into_mlflow
    mlflow.sklearn.log_model(
  File "C:\Users\hp\anaconda3\Lib\site-packages\mlflow\sklearn\__init__.py", line 426, in log_model
    return Model.log(
           ^^^^^^^^^^
  File "C:\Users\hp\anaconda3\Lib\site-packages\mlflow\models\model.py", line 1161, in log
    model = mlflow.initialize_logged_model(
            ^^^^^^^^^^^^^^^^^^^^^^^^^^^^^^^
  File "C:\Users\hp\anaconda3\Lib\site-packages\mlflow\tracking\fluent.py", line 2130, in initialize_logged_model
    model = _create_logged_model(
            ^^^^^^^^^^^^^^^^^^^^^
  File "C:\Users\hp\anaconda3\Lib\site-packages\mlflow\tracking\fluent.py", line 2257, in _create_logged_model
    return MlflowClient().create_logged_model(
           ^^^^^^^^^^^^^^^^^^^^^^^^^^^^^^^^^^^
  File "C:\Users\hp\anaconda3\Lib\site-packages\mlflow\tracking\client.py", line 5371, in create_logged_model
    return self._tracking_client.create_logged_model(
           ^^^^^^^^^^^^^^^^^^^^^^^^^^^^^^^^^^^^^^^^^^
  File "C:\Users\hp\anaconda3\Lib\site-packages\mlflow\tracking\_tracking_service\client.py", line 824, in create_logged_model
    return self.store.create_logged_model(
           ^^^^^^^^^^^^^^^^^^^^^^^^^^^^^^^
  File "C:\Users\hp\anaconda3\Lib\site-packages\mlflow\store\tracking\rest_store.py", line 936, in create_logged_model
    response_proto = self._call_endpoint(CreateLoggedModel, req_body)
                     ^^^^^^^^^^^^^^^^^^^^^^^^^^^^^^^^^^^^^^^^^^^^^^^^
  File "C:\Users\hp\anaconda3\Lib\site-packages\mlflow\store\tracking\rest_store.py", line 135, in _call_endpoint
    return call_endpoint(
           ^^^^^^^^^^^^^^
  File "C:\Users\hp\anaconda3\Lib\site-packages\mlflow\utils\rest_utils.py", line 590, in call_endpoint
    response = verify_rest_response(response, endpoint)
               ^^^^^^^^^^^^^^^^^^^^^^^^^^^^^^^^^^^^^^^^
  File "C:\Users\hp\anaconda3\Lib\site-packages\mlflow\utils\rest_utils.py", line 304, in verify_rest_response
    raise RestException(json.loads(response.text))
mlflow.exceptions.RestException: INTERNAL_ERROR: Response: {'error': 'unsupported endpoint, please contact support@dagshub.com'}

During handling of the above exception, another exception occurred:

Traceback (most recent call last):
  File "D:\data science and AI\2. MLOPS COURSE BY KRISH\14. First Project\byme\datascineceproject\main.py", line 54, in <module>
    obj.intitate_model_evaluation_pipeline()
  File "D:\data science and AI\2. MLOPS COURSE BY KRISH\14. First Project\byme\datascineceproject\src\datascience\pipeline\model_evaluation_pipeline.py", line 14, in intitate_model_evaluation_pipeline
    model_evaluation.log_into_mlflow()
  File "D:\data science and AI\2. MLOPS COURSE BY KRISH\14. First Project\byme\datascineceproject\src\datascience\components\model_evaluation.py", line 60, in log_into_mlflow
    mlflow.sklearn.log_model(model, "model")
  File "C:\Users\hp\anaconda3\Lib\site-packages\mlflow\sklearn\__init__.py", line 426, in log_model
    return Model.log(
           ^^^^^^^^^^
  File "C:\Users\hp\anaconda3\Lib\site-packages\mlflow\models\model.py", line 1161, in log
    model = mlflow.initialize_logged_model(
            ^^^^^^^^^^^^^^^^^^^^^^^^^^^^^^^
  File "C:\Users\hp\anaconda3\Lib\site-packages\mlflow\tracking\fluent.py", line 2130, in initialize_logged_model
    model = _create_logged_model(
            ^^^^^^^^^^^^^^^^^^^^^
  File "C:\Users\hp\anaconda3\Lib\site-packages\mlflow\tracking\fluent.py", line 2257, in _create_logged_model
    return MlflowClient().create_logged_model(
           ^^^^^^^^^^^^^^^^^^^^^^^^^^^^^^^^^^^
  File "C:\Users\hp\anaconda3\Lib\site-packages\mlflow\tracking\client.py", line 5371, in create_logged_model
    return self._tracking_client.create_logged_model(
           ^^^^^^^^^^^^^^^^^^^^^^^^^^^^^^^^^^^^^^^^^^
  File "C:\Users\hp\anaconda3\Lib\site-packages\mlflow\tracking\_tracking_service\client.py", line 824, in create_logged_model
    return self.store.create_logged_model(
           ^^^^^^^^^^^^^^^^^^^^^^^^^^^^^^^
  File "C:\Users\hp\anaconda3\Lib\site-packages\mlflow\store\tracking\rest_store.py", line 936, in create_logged_model
    response_proto = self._call_endpoint(CreateLoggedModel, req_body)
                     ^^^^^^^^^^^^^^^^^^^^^^^^^^^^^^^^^^^^^^^^^^^^^^^^
  File "C:\Users\hp\anaconda3\Lib\site-packages\mlflow\store\tracking\rest_store.py", line 135, in _call_endpoint
    return call_endpoint(
           ^^^^^^^^^^^^^^
  File "C:\Users\hp\anaconda3\Lib\site-packages\mlflow\utils\rest_utils.py", line 590, in call_endpoint
    response = verify_rest_response(response, endpoint)
               ^^^^^^^^^^^^^^^^^^^^^^^^^^^^^^^^^^^^^^^^
  File "C:\Users\hp\anaconda3\Lib\site-packages\mlflow\utils\rest_utils.py", line 304, in verify_rest_response
    raise RestException(json.loads(response.text))
mlflow.exceptions.RestException: INTERNAL_ERROR: Response: {'error': 'unsupported endpoint, please contact support@dagshub.com'}
[2025-09-06 12:13:40,139: INFO: utils : NumExpr defaulting to 8 threads.]
[2025-09-06 12:13:43,148: INFO: main : >>>>>> stage Data Ingestion stage started <<<<<<]
[2025-09-06 12:13:43,152: INFO: common : created directory at: artifacts]
[2025-09-06 12:13:43,152: INFO: common : created directory at: artifacts/data_ingestion]
[2025-09-06 12:13:43,153: INFO: data_ingestion : File already exists]
[2025-09-06 12:13:43,156: INFO: main : >>>>>> stage Data Ingestion stage completed <<<<<<

x==========x]
[2025-09-06 12:13:43,156: INFO: main : >>>>>> stage Data Validation stage started <<<<<<]
[2025-09-06 12:13:43,162: INFO: common : created directory at: artifacts]
[2025-09-06 12:13:43,162: INFO: common : created directory at: artifacts/data_validation]
[2025-09-06 12:13:43,169: INFO: main : >>>>>> stage Data Validation stage completed <<<<<<

x==========x]
[2025-09-06 12:13:43,170: INFO: main : >>>>>> stage Data Transformation stage started <<<<<<]
[2025-09-06 12:13:43,174: INFO: common : created directory at: artifacts]
[2025-09-06 12:13:43,175: INFO: common : created directory at: artifacts/data_transformation]
[2025-09-06 12:13:43,201: INFO: data_transformation : Splited data into training and test sets]
[2025-09-06 12:13:43,201: INFO: data_transformation : (1199, 12)]
[2025-09-06 12:13:43,202: INFO: data_transformation : (400, 12)]
[2025-09-06 12:13:43,202: INFO: main : >>>>>> stage Data Transformation stage completed <<<<<<

x==========x]
[2025-09-06 12:13:43,203: INFO: main : >>>>>> stage Model Training stage started <<<<<<]
[2025-09-06 12:13:43,208: INFO: common : created directory at: artifacts]
[2025-09-06 12:13:43,209: INFO: common : created directory at: artifacts/model_trainer]
[2025-09-06 12:13:43,236: INFO: main : >>>>>> stage Model Training stage completed <<<<<<

x==========x]
[2025-09-06 12:13:43,237: INFO: main : >>>>>> stage Model Evaluation stage started <<<<<<]
[2025-09-06 12:13:43,241: INFO: common : created directory at: artifacts]
[2025-09-06 12:13:43,241: INFO: common : created directory at: artifacts/model_evaluation]
[2025-09-06 12:13:44,625: INFO: common : json file saved at: artifacts\model_evaluation\metrics.json]
[2025-09-06 12:13:52,183: ERROR: main : INTERNAL_ERROR: Response: {'error': 'unsupported endpoint, please contact support@dagshub.com'}]
Traceback (most recent call last):
  File "D:\data science and AI\2. MLOPS COURSE BY KRISH\14. First Project\byme\datascineceproject\src\datascience\components\model_evaluation.py", line 52, in log_into_mlflow
    mlflow.sklearn.log_model(
  File "C:\Users\hp\anaconda3\Lib\site-packages\mlflow\sklearn\__init__.py", line 426, in log_model
    return Model.log(
           ^^^^^^^^^^
  File "C:\Users\hp\anaconda3\Lib\site-packages\mlflow\models\model.py", line 1161, in log
    model = mlflow.initialize_logged_model(
            ^^^^^^^^^^^^^^^^^^^^^^^^^^^^^^^
  File "C:\Users\hp\anaconda3\Lib\site-packages\mlflow\tracking\fluent.py", line 2130, in initialize_logged_model
    model = _create_logged_model(
            ^^^^^^^^^^^^^^^^^^^^^
  File "C:\Users\hp\anaconda3\Lib\site-packages\mlflow\tracking\fluent.py", line 2257, in _create_logged_model
    return MlflowClient().create_logged_model(
           ^^^^^^^^^^^^^^^^^^^^^^^^^^^^^^^^^^^
  File "C:\Users\hp\anaconda3\Lib\site-packages\mlflow\tracking\client.py", line 5371, in create_logged_model
    return self._tracking_client.create_logged_model(
           ^^^^^^^^^^^^^^^^^^^^^^^^^^^^^^^^^^^^^^^^^^
  File "C:\Users\hp\anaconda3\Lib\site-packages\mlflow\tracking\_tracking_service\client.py", line 824, in create_logged_model
    return self.store.create_logged_model(
           ^^^^^^^^^^^^^^^^^^^^^^^^^^^^^^^
  File "C:\Users\hp\anaconda3\Lib\site-packages\mlflow\store\tracking\rest_store.py", line 936, in create_logged_model
    response_proto = self._call_endpoint(CreateLoggedModel, req_body)
                     ^^^^^^^^^^^^^^^^^^^^^^^^^^^^^^^^^^^^^^^^^^^^^^^^
  File "C:\Users\hp\anaconda3\Lib\site-packages\mlflow\store\tracking\rest_store.py", line 135, in _call_endpoint
    return call_endpoint(
           ^^^^^^^^^^^^^^
  File "C:\Users\hp\anaconda3\Lib\site-packages\mlflow\utils\rest_utils.py", line 590, in call_endpoint
    response = verify_rest_response(response, endpoint)
               ^^^^^^^^^^^^^^^^^^^^^^^^^^^^^^^^^^^^^^^^
  File "C:\Users\hp\anaconda3\Lib\site-packages\mlflow\utils\rest_utils.py", line 304, in verify_rest_response
    raise RestException(json.loads(response.text))
mlflow.exceptions.RestException: INTERNAL_ERROR: Response: {'error': 'unsupported endpoint, please contact support@dagshub.com'}

During handling of the above exception, another exception occurred:

Traceback (most recent call last):
  File "D:\data science and AI\2. MLOPS COURSE BY KRISH\14. First Project\byme\datascineceproject\main.py", line 54, in <module>
    obj.intitate_model_evaluation_pipeline()
  File "D:\data science and AI\2. MLOPS COURSE BY KRISH\14. First Project\byme\datascineceproject\src\datascience\pipeline\model_evaluation_pipeline.py", line 14, in intitate_model_evaluation_pipeline
    model_evaluation.log_into_mlflow()
  File "D:\data science and AI\2. MLOPS COURSE BY KRISH\14. First Project\byme\datascineceproject\src\datascience\components\model_evaluation.py", line 60, in log_into_mlflow
    mlflow.sklearn.log_model(model, "model")
  File "C:\Users\hp\anaconda3\Lib\site-packages\mlflow\sklearn\__init__.py", line 426, in log_model
    return Model.log(
           ^^^^^^^^^^
  File "C:\Users\hp\anaconda3\Lib\site-packages\mlflow\models\model.py", line 1161, in log
    model = mlflow.initialize_logged_model(
            ^^^^^^^^^^^^^^^^^^^^^^^^^^^^^^^
  File "C:\Users\hp\anaconda3\Lib\site-packages\mlflow\tracking\fluent.py", line 2130, in initialize_logged_model
    model = _create_logged_model(
            ^^^^^^^^^^^^^^^^^^^^^
  File "C:\Users\hp\anaconda3\Lib\site-packages\mlflow\tracking\fluent.py", line 2257, in _create_logged_model
    return MlflowClient().create_logged_model(
           ^^^^^^^^^^^^^^^^^^^^^^^^^^^^^^^^^^^
  File "C:\Users\hp\anaconda3\Lib\site-packages\mlflow\tracking\client.py", line 5371, in create_logged_model
    return self._tracking_client.create_logged_model(
           ^^^^^^^^^^^^^^^^^^^^^^^^^^^^^^^^^^^^^^^^^^
  File "C:\Users\hp\anaconda3\Lib\site-packages\mlflow\tracking\_tracking_service\client.py", line 824, in create_logged_model
    return self.store.create_logged_model(
           ^^^^^^^^^^^^^^^^^^^^^^^^^^^^^^^
  File "C:\Users\hp\anaconda3\Lib\site-packages\mlflow\store\tracking\rest_store.py", line 936, in create_logged_model
    response_proto = self._call_endpoint(CreateLoggedModel, req_body)
                     ^^^^^^^^^^^^^^^^^^^^^^^^^^^^^^^^^^^^^^^^^^^^^^^^
  File "C:\Users\hp\anaconda3\Lib\site-packages\mlflow\store\tracking\rest_store.py", line 135, in _call_endpoint
    return call_endpoint(
           ^^^^^^^^^^^^^^
  File "C:\Users\hp\anaconda3\Lib\site-packages\mlflow\utils\rest_utils.py", line 590, in call_endpoint
    response = verify_rest_response(response, endpoint)
               ^^^^^^^^^^^^^^^^^^^^^^^^^^^^^^^^^^^^^^^^
  File "C:\Users\hp\anaconda3\Lib\site-packages\mlflow\utils\rest_utils.py", line 304, in verify_rest_response
    raise RestException(json.loads(response.text))
mlflow.exceptions.RestException: INTERNAL_ERROR: Response: {'error': 'unsupported endpoint, please contact support@dagshub.com'}
[2025-09-06 12:18:25,889: INFO: utils : NumExpr defaulting to 8 threads.]
[2025-09-06 12:18:28,848: INFO: main : >>>>>> stage Data Ingestion stage started <<<<<<]
[2025-09-06 12:18:28,852: INFO: common : created directory at: artifacts]
[2025-09-06 12:18:28,852: INFO: common : created directory at: artifacts/data_ingestion]
[2025-09-06 12:18:28,853: INFO: data_ingestion : File already exists]
[2025-09-06 12:18:28,855: INFO: main : >>>>>> stage Data Ingestion stage completed <<<<<<

x==========x]
[2025-09-06 12:18:28,856: INFO: main : >>>>>> stage Data Validation stage started <<<<<<]
[2025-09-06 12:18:28,861: INFO: common : created directory at: artifacts]
[2025-09-06 12:18:28,862: INFO: common : created directory at: artifacts/data_validation]
[2025-09-06 12:18:28,868: INFO: main : >>>>>> stage Data Validation stage completed <<<<<<

x==========x]
[2025-09-06 12:18:28,868: INFO: main : >>>>>> stage Data Transformation stage started <<<<<<]
[2025-09-06 12:18:28,874: INFO: common : created directory at: artifacts]
[2025-09-06 12:18:28,875: INFO: common : created directory at: artifacts/data_transformation]
[2025-09-06 12:18:28,901: INFO: data_transformation : Splited data into training and test sets]
[2025-09-06 12:18:28,901: INFO: data_transformation : (1199, 12)]
[2025-09-06 12:18:28,902: INFO: data_transformation : (400, 12)]
[2025-09-06 12:18:28,902: INFO: main : >>>>>> stage Data Transformation stage completed <<<<<<

x==========x]
[2025-09-06 12:18:28,902: INFO: main : >>>>>> stage Model Training stage started <<<<<<]
[2025-09-06 12:18:28,907: INFO: common : created directory at: artifacts]
[2025-09-06 12:18:28,907: INFO: common : created directory at: artifacts/model_trainer]
[2025-09-06 12:18:28,936: INFO: main : >>>>>> stage Model Training stage completed <<<<<<

x==========x]
[2025-09-06 12:18:28,937: INFO: main : >>>>>> stage Model Evaluation stage started <<<<<<]
[2025-09-06 12:18:28,941: INFO: common : created directory at: artifacts]
[2025-09-06 12:18:28,942: INFO: common : created directory at: artifacts/model_evaluation]
[2025-09-06 12:18:30,403: INFO: common : json file saved at: artifacts\model_evaluation\metrics.json]
[2025-09-06 12:18:49,238: INFO: main : >>>>>> stage Model Evaluation stage completed <<<<<<

x==========x]
[2025-09-06 14:49:02,597: INFO: _internal : [31m[1mWARNING: This is a development server. Do not use it in a production deployment. Use a production WSGI server instead.[0m
 * Running on all addresses (0.0.0.0)
 * Running on http://127.0.0.1:8000
 * Running on http://127.0.0.1:8000]
[2025-09-06 14:49:02,598: INFO: _internal : [33mPress CTRL+C to quit[0m]
[2025-09-06 14:49:20,233: INFO: _internal : 127.0.0.1 - - [06/Sep/2025 14:49:20] "GET / HTTP/1.1" 200 -]
[2025-09-06 14:49:20,305: INFO: _internal : 127.0.0.1 - - [06/Sep/2025 14:49:20] "[33mGET /static/assets/img/form-v9.jpg HTTP/1.1[0m" 404 -]
[2025-09-06 14:49:20,442: INFO: _internal : 127.0.0.1 - - [06/Sep/2025 14:49:20] "GET / HTTP/1.1" 200 -]
[2025-09-06 14:49:20,606: INFO: _internal : 127.0.0.1 - - [06/Sep/2025 14:49:20] "[33mGET /favicon.ico HTTP/1.1[0m" 404 -]
[2025-09-06 14:49:36,677: INFO: _internal : 127.0.0.1 - - [06/Sep/2025 14:49:36] "POST /predict HTTP/1.1" 200 -]
[2025-09-06 14:49:36,720: INFO: _internal : 127.0.0.1 - - [06/Sep/2025 14:49:36] "GET /predict HTTP/1.1" 200 -]
[2025-09-06 14:49:48,226: INFO: _internal : 127.0.0.1 - - [06/Sep/2025 14:49:48] "[33mGET /result HTTP/1.1[0m" 404 -]
[2025-09-06 14:49:48,283: INFO: _internal : 127.0.0.1 - - [06/Sep/2025 14:49:48] "[33mGET /result HTTP/1.1[0m" 404 -]
[2025-09-06 14:50:09,250: INFO: _internal : 127.0.0.1 - - [06/Sep/2025 14:50:09] "[33mGET /result HTTP/1.1[0m" 404 -]
[2025-09-06 14:50:09,279: INFO: _internal : 127.0.0.1 - - [06/Sep/2025 14:50:09] "[33mGET /result HTTP/1.1[0m" 404 -]
[2025-09-06 14:50:14,526: INFO: _internal : 127.0.0.1 - - [06/Sep/2025 14:50:14] "GET / HTTP/1.1" 200 -]
[2025-09-06 14:50:14,577: INFO: _internal : 127.0.0.1 - - [06/Sep/2025 14:50:14] "[33mGET /static/assets/img/form-v9.jpg HTTP/1.1[0m" 404 -]
[2025-09-06 14:50:14,579: INFO: _internal : 127.0.0.1 - - [06/Sep/2025 14:50:14] "GET / HTTP/1.1" 200 -]
[2025-09-06 14:50:46,693: INFO: _internal : 127.0.0.1 - - [06/Sep/2025 14:50:46] "POST /predict HTTP/1.1" 200 -]
[2025-09-06 14:50:46,740: INFO: _internal : 127.0.0.1 - - [06/Sep/2025 14:50:46] "GET /predict HTTP/1.1" 200 -]
[2025-09-06 14:53:30,277: INFO: _internal : 127.0.0.1 - - [06/Sep/2025 14:53:30] "POST /predict HTTP/1.1" 200 -]
[2025-09-06 14:53:30,309: INFO: _internal : 127.0.0.1 - - [06/Sep/2025 14:53:30] "GET /predict HTTP/1.1" 200 -]
[2025-09-06 14:53:45,865: INFO: _internal : [31m[1mWARNING: This is a development server. Do not use it in a production deployment. Use a production WSGI server instead.[0m
 * Running on all addresses (0.0.0.0)
 * Running on http://127.0.0.1:8000
 * Running on http://10.25.182.130:8000]
[2025-09-06 14:53:45,865: INFO: _internal : [33mPress CTRL+C to quit[0m]
[2025-09-06 14:53:50,726: INFO: _internal : 127.0.0.1 - - [06/Sep/2025 14:53:50] "GET / HTTP/1.1" 200 -]
[2025-09-06 14:53:50,836: INFO: _internal : 127.0.0.1 - - [06/Sep/2025 14:53:50] "GET / HTTP/1.1" 200 -]
[2025-09-06 14:53:50,837: INFO: _internal : 127.0.0.1 - - [06/Sep/2025 14:53:50] "[33mGET /static/assets/img/form-v9.jpg HTTP/1.1[0m" 404 -]
[2025-09-06 14:54:09,680: INFO: _internal : 127.0.0.1 - - [06/Sep/2025 14:54:09] "POST /predict HTTP/1.1" 200 -]
[2025-09-06 14:54:09,752: INFO: _internal : 127.0.0.1 - - [06/Sep/2025 14:54:09] "GET /predict HTTP/1.1" 200 -]
[2025-09-06 14:58:00,893: INFO: _internal : [31m[1mWARNING: This is a development server. Do not use it in a production deployment. Use a production WSGI server instead.[0m
 * Running on all addresses (0.0.0.0)
 * Running on http://127.0.0.1:8000
 * Running on http://10.25.182.130:8000]
[2025-09-06 14:58:00,894: INFO: _internal : [33mPress CTRL+C to quit[0m]
[2025-09-06 14:58:03,419: INFO: _internal : 127.0.0.1 - - [06/Sep/2025 14:58:03] "GET / HTTP/1.1" 200 -]
[2025-09-06 14:58:03,888: INFO: _internal : 127.0.0.1 - - [06/Sep/2025 14:58:03] "[33mGET /static/assets/img/form-v9.jpg HTTP/1.1[0m" 404 -]
[2025-09-06 14:58:03,890: INFO: _internal : 127.0.0.1 - - [06/Sep/2025 14:58:03] "GET / HTTP/1.1" 200 -]
[2025-09-06 14:58:25,187: INFO: _internal : 127.0.0.1 - - [06/Sep/2025 14:58:25] "POST /predict HTTP/1.1" 200 -]
[2025-09-06 14:58:25,234: INFO: _internal : 127.0.0.1 - - [06/Sep/2025 14:58:25] "GET /predict HTTP/1.1" 200 -]
[2025-09-06 14:58:34,897: INFO: _internal : 127.0.0.1 - - [06/Sep/2025 14:58:34] "POST /predict HTTP/1.1" 200 -]
[2025-09-06 14:58:34,935: INFO: _internal : 127.0.0.1 - - [06/Sep/2025 14:58:34] "GET /predict HTTP/1.1" 200 -]
[2025-09-06 14:59:06,617: INFO: _internal : [31m[1mWARNING: This is a development server. Do not use it in a production deployment. Use a production WSGI server instead.[0m
 * Running on all addresses (0.0.0.0)
 * Running on http://127.0.0.1:8000
 * Running on http://10.25.182.130:8000]
[2025-09-06 14:59:06,618: INFO: _internal : [33mPress CTRL+C to quit[0m]
[2025-09-06 14:59:13,801: INFO: _internal : 10.25.182.130 - - [06/Sep/2025 14:59:13] "GET / HTTP/1.1" 200 -]
[2025-09-06 14:59:13,890: INFO: _internal : 10.25.182.130 - - [06/Sep/2025 14:59:13] "[33mGET /static/assets/img/form-v9.jpg HTTP/1.1[0m" 404 -]
[2025-09-06 14:59:13,891: INFO: _internal : 10.25.182.130 - - [06/Sep/2025 14:59:13] "GET / HTTP/1.1" 200 -]
[2025-09-06 14:59:14,206: INFO: _internal : 10.25.182.130 - - [06/Sep/2025 14:59:14] "[33mGET /favicon.ico HTTP/1.1[0m" 404 -]
[2025-09-06 14:59:33,034: INFO: _internal : 10.25.182.130 - - [06/Sep/2025 14:59:33] "POST /predict HTTP/1.1" 200 -]
[2025-09-06 14:59:33,097: INFO: _internal : 10.25.182.130 - - [06/Sep/2025 14:59:33] "GET /predict HTTP/1.1" 200 -]
[2025-09-06 15:02:21,618: INFO: _internal : [31m[1mWARNING: This is a development server. Do not use it in a production deployment. Use a production WSGI server instead.[0m
 * Running on all addresses (0.0.0.0)
 * Running on http://127.0.0.1:8000
 * Running on http://10.25.182.130:8000]
[2025-09-06 15:02:21,619: INFO: _internal : [33mPress CTRL+C to quit[0m]
[2025-09-06 15:02:26,276: INFO: _internal : 10.25.182.130 - - [06/Sep/2025 15:02:26] "GET / HTTP/1.1" 200 -]
[2025-09-06 15:02:26,822: INFO: _internal : 10.25.182.130 - - [06/Sep/2025 15:02:26] "GET / HTTP/1.1" 200 -]
[2025-09-06 15:02:26,829: INFO: _internal : 10.25.182.130 - - [06/Sep/2025 15:02:26] "[33mGET /static/assets/img/form-v9.jpg HTTP/1.1[0m" 404 -]
[2025-09-06 15:02:46,646: INFO: _internal : 10.25.182.130 - - [06/Sep/2025 15:02:46] "POST /predict HTTP/1.1" 200 -]
[2025-09-06 15:02:46,694: INFO: _internal : 10.25.182.130 - - [06/Sep/2025 15:02:46] "GET /predict HTTP/1.1" 200 -]
